Workbook

Sheet Đọc trước
A1: HƯỚNG DẪM DÙNG FILE — PrintGrid: kế hoạch hoàn thiện & phân công
A3: Sheet | B3: Dùng để | C3: Ai cập nhật
A4: 1. Phân công FR | B4: 43 chức năng của hệ thống, chia theo nhóm S1–S9, kèm HIỆN TRẠNG code thật (kiểm kê 25/09). Mỗi dòng chọn NGƯỜI PHỤ TRÁCH. | C4: Mỗi người tự chọn tên ở dòng mình nhận
A5: 2. WBS | B5: Việc cụ thể để làm xong các FR: từng dòng là 1 đầu việc + tiêu chí nghiệm thu AC. Chọn người + đánh dấu tiến độ tại đây. | C5: Người làm cập nhật Trạng thái mỗi tối
A6: 3. TV | B6: Tải của 4 người tự động cộng từ WBS. Chênh quá 5 ngày → nhượng dòng "Nên làm/Có thì tốt". | C6: Tự động
A7: 4. Tiến trình | B7: 6 giai đoạn + 2 cổng kiểm tra (G-A tuần 2, G-B tuần 8). Không qua cổng thì không đi tiếp. | C7: Cả nhóm chốt tại họp
A8: 5. Ai làm màn nào | B8: Mỗi màn hình FE có đúng 1 chủ trong 1 tuần — tránh 2 người sửa cùng 1 file. | C8: Theo WBS
A10: Tài liệu chi tiết (SRS) xem tại: | B10: documentation/project/requirements/ — 09 (FR + Acceptance), 12 (Use Case từng màn), 13 (ca kiểm thử). WBS dẫn ngược mã FR/UC để tra.
A11: Nguyên tắc vàng: | B11: Nhìn vào WBS là biết: LÀM GỠ — Ở ĐÂU — XONG LÀ THẾ NÀO — AI LÀM — TUẦN NÀO. Không cần hỏi thêm ai.

Sheet 1. Phân công FR
A1: STT | B1: Mã FR | C1: Chức năng | D1: Actor | E1: Hiện trạng code (audit 25/09) | F1: Người phụ trách (chọn) | G1: Việc WBS làm nó xong | H1: Tiến độ (chọn) | I1: Ghi chú
B2: S1. Quản lý tài khoản & Phân quyền
A3: 1 | B3: FR-CUST-001 | C3: Đăng ký / đăng nhập / email xác thực / hồ sơ + địa chỉ nhận hàng | D3: Khách hàng | E3: Đã làm một phần — thiếu verify email & địa chỉ | H3: Chưa làm | I3: 1, 5, 6
A4: 2 | B4: FR-ADMIN-001 | C4: Quản lý tài khoản & phân quyền các vai (tạo, khóa, đổi role) | D4: Admin | E4: Chưa có — role đang hardcode theo email | H4: Chưa làm | I4: 2, 11
A5: 3 | B5: FR-ADMIN-004 | C5: Nhật ký hệ thống (audit) + theo dõi sức khỏe tiến trình nền | D5: Admin | E5: Chưa có audit; Hangfire dashboard đã có | H5: Chưa làm | I5: 7
B6: S2. Danh mục & Cấu hình hệ thống
A7: 4 | B7: FR-ADMIN-002 | C7: Cấu hình tham số thương mại (giá, trọng số, hạn báo giá…) không cần tái triển khai | D7: Admin | E7: Chưa có | H7: Chưa làm | I7: 30
A8: 5 | B8: FR-ADMIN-003 | C8: Danh mục dùng chung: vật liệu, màu, công nghệ, cấp chất lượng | D8: Admin | E8: Chưa có — đang hardcode trong code | H8: Chưa làm | I8: 44
A9: 6 | B9: FR-ADMIN-005 | C9: Quản lý bộ kiểm hàng (checklist) & danh mục lỗi | D9: Admin | E9: Chưa có | H9: Chưa làm | I9: 42
B10: S3. Model & Báo giá phía Khách
A11: 7 | B11: FR-CUST-002 | C11: Tải file 3D (STL/OBJ/3MF ≤50MB) về vùng lưu trữ riêng | D11: Khách hàng | E11: Đã làm một phần — thiếu chặn định dạng + quota | H11: Đang làm | I11: —
A12: 8 | B12: FR-CUST-003 | C12: Xem trước model 3D trong trình duyệt kèm kích thước | D12: Khách hàng | E12: Chưa có | H12: Chưa làm | I12: —
A13: 9 | B13: FR-CUST-004 | C13: Kiểm tra model in được hay không + cảnh báo oversized | D13: Khách hàng | E13: Chưa có — pipeline đang dùng số giả | H13: Chưa làm | I13: 13
A14: 10 | B14: FR-CUST-005 | C14: Khai thông số in: vật liệu, màu, lớp, đặc, gia công, số lượng | D14: Khách hàng | E14: Đã làm một phần — thiếu gia công/cấp dịch vụ | H14: Đang làm | I14: —
A15: 11 | B15: FR-CUST-006 | C15: Nhận báo giá tự động: breakdown + ngày giao cam kết + hạn dùng | D15: Khách hàng | E15: Đã làm một phần — giá hằng số, ngày +3 ngày | H15: Đang làm | I15: 14, 15, 16
A16: 12 | B16: FR-CUST-010 | C16: Thư viện model cá nhân + đặt lại nhanh | D16: Khách hàng | E16: Đã làm một phần — chưa nhớ cấu hình cũ | H16: Đang làm | I16: —
B17: S4. Đơn hàng & Thanh toán
A18: 13 | B18: FR-CUST-007 | C18: Xác nhận báo giá thành đơn (địa chỉ, điều khoản) | D18: Khách hàng | E18: Đã làm một phần — thiếu điều khoản | H18: Đang làm | I18: 10, 23
A19: 14 | B19: FR-CUST-008 | C19: Thanh toán thật qua cổng SEPay (QR + xác thực 2 lớp) | D19: Khách hàng | E19: Chưa có — tuần 1–2 dùng cầu tạm đánh dấu đã trả | H19: Chưa làm | I19: 24
A20: 15 | B20: FR-ANAL-005 | C20: Duyệt & hoàn tiền + đối soát sổ thu hằng ngày | D20: Quản trị mạng | E20: Chưa có | H20: Chưa làm | I20: 26
B21: S5. Theo dõi đơn & Chăm sóc sau bán
A22: 16 | B22: FR-CUST-009 | C22: Theo dõi đơn realtime, không lộ tên xưởng in | D22: Khách hàng | E22: Đã làm một phần — realtime chưa bật | H22: Đang làm | I22: 27
A23: 17 | B23: FR-CUST-011 | C23: Xin in lại / khiếu nại trong hạn bảo hành 30 ngày | D23: Khách hàng | E23: Chưa có | H23: Chưa làm | I23: 37
B24: S6. Xưởng in: đăng ký, máy, kho, vận hành
A25: 18 | B25: FR-LAB-001 | C25: Xưởng tự đăng ký + admin duyệt (lịch làm, thời gian chuyển về hub) | D25: Quản lý xưởng | E25: Chưa có | H25: Chưa làm | I25: 43
A26: 19 | B26: FR-LAB-002 | C26: Khai báo & quản lý máy in (công nghệ, khổ, dung sai, trạng thái) | D26: Quản lý xưởng | E26: Đã làm một phần — API có, thiếu màn hình | H26: Đang làm | I26: 32
A27: 20 | B27: FR-LAB-003 | C27: Kho vật liệu theo màu, trừ dần theo job, cảnh báo hết | D27: Quản lý xưởng | E27: Chưa có | H27: Chưa làm | I27: 33
A28: 21 | B28: FR-LAB-004 | C28: Nhận/từ chối job được giao trong hạn 2 giờ | D28: Quản lý xưởng | E28: Đã làm một phần — thiếu từ chối + đếm giờ | H28: Đang làm | I28: 21
A29: 22 | B29: FR-LAB-005 | C29: Vận hành in: chờ→đang in→xong, khai số liệu thực tế, báo sự cố | D29: Thợ in | E29: Đã làm một phần — thiếu sự cố + phân theo xưởng | H29: Đang làm | I29: 34, 35
A30: 23 | B30: FR-LAB-006 | C30: Xem lịch máy theo dòng thời gian | D30: Quản lý xưởng | E30: Chưa có | H30: Chưa làm | I30: 46
A31: 24 | B31: FR-LAB-007 | C31: Xem điểm hiệu năng của xưởng mình | D31: Quản lý xưởng | E31: Chưa có | H31: Chưa làm | I31: 46
B32: S7. Hub: nhập hàng, kiểm tra, đóng gói, giao
A33: 25 | B33: FR-HUB-001 | C33: Nhận lô từ xưởng, đối chiếu thiếu/hỏng | D33: QC hub | E33: Chưa có | H33: Chưa làm | I33: 28
A34: 26 | B34: FR-HUB-002 | C34: Kiểm hàng theo checklist cấp chất lượng + ảnh + quy lỗi | D34: QC hub | E34: Đã làm một phần — chỉ có đậu/trượt | H34: Đang làm | I34: 40
A35: 27 | B35: FR-HUB-003 | C35: Phát lệnh in lại + xác nhận lịch cam kết mới | D35: QC hub | E35: Đã làm một phần — thiếu hạn mức + deadline gốc | H35: Đang làm | I35: 18, 40
A36: 28 | B36: FR-HUB-004 | C36: Gộp đơn, chặn đóng gói khi còn thiếu món đậu kiểm | D36: Thủ kho hub | E36: Chưa có | H36: Chưa làm | I36: 29
A37: 29 | B37: FR-HUB-005 | C37: Đóng gói, ghi vận đơn, xác nhận giao → mở bảo hành 30 ngày | D37: Thủ kho hub | E37: Chưa có | H37: Chưa làm | I37: 29
B38: S8. Engine: phân tích, định giá, điều phối, lịch
A39: 30 | B39: FR-SCHED-001 | C39: Phân tích hình học model: kích thước, thể tích, lỗi mesh | D39: Hệ thống | E39: Đã làm một phần — parser có nhưng không được gọi | H39: Đang làm | I39: 13
A40: 31 | B40: FR-SCHED-002 | C40: Cắt lớp ảo: ước lượng thời gian in + vật liệu | D40: Hệ thống | E40: Đã làm một phần — heuristic, nguồn dữ liệu giả | H40: Đang làm | I40: 14
...

Sheet 2. WBS
A1: ID | B1: Đơn vị | C1: Đầu việc | D1: Chi tiết & tiêu chí nghiệm thu | E1: Tuần | F1: Công (ngày) | G1: Người làm (chọn) | H1: Trạng thái (chọn)
A2: 1 | B2: Cả nhóm | C2: Họp khóa hợp đồng API + quy ước repo | D2: Là lập trình viên, tôi cần mọi bên thống nhất DTO + tên event trước khi code. AC01: File contracts/openapi.yaml chứa DTO Order/Quote/Job/Slot + tên event (job.assigned, job.failed, qc.failed…). AC02: 4 máy clone về docker compose up chạy được liên thông. AC03: Đổi schema phải sửa openapi trước, code sau. Mọi PR chạm shared/ qua chủ shell. | E2: 1 | F2: 1 | H2: Chưa làm
A3: 2 | B3: Backend | C3: Bảng người dùng + vai thật (thay hardcode email) | D3: Là admin, tôi có thể tạo tài khoản và gán vai. AC01: Bảng user_roles; JWT claim đọc từ DB, bỏ DemoRoles. AC02: Tài khoản lab@/qc@/ops@ cũ phải dựng lại bằng màn admin (tuần 4) hoặc đăng ký tạm. AC03: Migration chạy được trên DB rỗng. | E3: 1 | F3: 3 | H3: Chưa làm
A4: 3 | B4: FE | C4: Chỉnh màn hình đăng ký: hết số liệu bịa | D4: Là khách mới, tôi không thấy số liệu "mẫu" nào trên màn hình. AC01: LoginShowcase còn 3D, đã bỏ 3 chip 128/64/12. AC02: HomePage chỉ hiển thị số từ /network/stats (đã đúng, giữ). AC03: Không hardcode số ở bất kỳ màn nào. | E4: 1 | F4: 0.5 | H4: Chưa làm
A5: 4 | B5: Backend | C5: Bỏ chạy dữ liệu mẫu lúc khởi động | D5: Là dev, tôi muốn DB sạch, có gì dùng nấy. AC01: DemoDataSeeder đã xóa khỏi Program.cs (xong 26/09). AC02: DB dev wipe bằng TRUNCATE một lần. AC03: Công cụ seed-dev riêng (không tự chạy) khi cần demo — làm cùng task 2. | E5: 1 | F5: 0.5 | H5: Chưa làm
A6: 5 | B6: Backend | C6: Xác thực email khi đăng ký | D6: Là khách, tôi phải xác thực email mới được đặt đơn. AC01: Cờ Verified + link token. AC02: Chưa verify ⇒ chặn create order kèm hướng dẫn. AC03: resend email có tần suất chặn. | E6: 1 | F6: 2 | H6: Chưa làm
A7: 6 | B7: FE+BE | C7: Địa chỉ nhận hàng: thêm/sửa/xóa/mặc định | D7: Là khách, tôi lưu địa chỉ dùng nhiều lần. AC01: CRUD + chọn mặc định ở checkout. AC02: Xóa bị chặn khi còn đơn chưa giao (409 + lý do). | E7: 1 | F7: 2 | H7: Chưa làm
A8: 13 | B8: Backend | C8: Nối parser có sẵn vào luồng phân tích | D8: Là khách, thông số của tôi tính từ file thật. AC01: AnalyzeModelJob tải file từ MinIO gọi StlMeshParser (bỏ phân tích metadata). AC02: thêm kiểm tra kín/nhiều cạnh; AC03: oversized chặn báo giá ngay từ FR-CUST-004. | E8: 1 | F8: 3 | H8: Chưa làm
A9: 14 | B9: Backend | C9: Ước lượng thời gian/vật liệu từ số phân tích | D9: AC01: heuristic đọc bounding box + thể tích thật. AC02: kết quả trả kèm cờ chưa hiệu chuẩn (calibration task 45). AC03: file 20 MB full < 60 giây (Hangfire + progress). | E9: 1 | F9: 3 | H9: Chưa làm
A10: 10 | B10: FE | C10: Bổ sung bước điều khoản vào trang đặt hàng | D10: AC01: không tick ⇒ nút xác nhận disable. AC02: đơn lưu kèm bản điều khoản đã đồng ý. | E10: 2 | F10: 1 | H10: Chưa làm
A11: 15 | B11: Backend | C11: Đặt lịch thử lúc báo giá — ngày giao từ năng lực thật | D11: AC01: CreateQuote chạy thử xếp lịch, không ghi slot thật. AC02: cùng cấu hình ở 2 thời điểm tải khác ⇒ ngày khác. AC03: không lab khả thi ⇒ từ chối báo giá có lý do. AC04: gấp ⇒ phụ phí (BR-QUOTE-001). | E11: 2 | F11: 5 | H11: Chưa làm
A12: 16 | B12: Backend | C12: Tách đơn thành job từ cấu hình thật + không trùng lịch | D12: AC01: bỏ hằng số 120³/30g/60ph; job đọc từ quote_items + phân tích. AC02: slot machine có ràng buộc chống chồng (EXCLUDE/lock). AC03: test 10 worker đặt song song ⇒ 0 trùng. | E12: 2 | F12: 4 | H12: Chưa làm
A13: 17 | B13: Backend | C13: Máy định giá + đóng băng kỳ giá vào báo giá | D13: AC01: công thức về module Scheduling, giá lấy từ bảng cấu hình có phiên bản (task 30). AC02: quote lưu config_version_id; tính lại ra đúng số cũ dù giá đã đổi. | E13: 2 | F13: 4 | H13: Chưa làm
... A54: 54 | B54: Cả nhóm | C54: Bug bash + 3 màn kịch bản demo + hồ sơ | D54: AC01: không còn việc "Phải làm" đang Block. AC02: 3 kịch bản chạy <10 phút mỗi kịch bản. AC03: hồ sơ 09–13 đánh dấu xong theo cột ở sheet 1. | E54: 8 | F54: 6 | H54: Chưa làm

Sheet 3. TV
A1: Tên | B1: Nhóm phụ trách chính (ghi) | C1: TẢI (tự cộng từ WBS) | D1: T1 | E1: T2 | F1: T3 | G1: T4 | H1: T5 | I1: T6 | J1: T7 | K1: T8
A2: Tân | C2: =SUM(D2:K2) -> 0 | D2: =SUMIFS('2. WBS'!$F:$F,'2. WBS'!$G:$G,$A2,'2. WBS'!$E:$E,1) -> 0 | E2: =SUMIFS('2. WBS'!$F:$F,'2. WBS'!$G:$G,$A2,'2. WBS'!$E:$E,2) -> 0 | F2: =SUMIFS('2. WBS'!$F:$F,'2. WBS'!$G:$G,$A2,'2. WBS'!$E:$E,3) -> 0 | G2: =SUMIFS('2. WBS'!$F:$F,'2. WBS'!$G:$G,$A2,'2. WBS'!$E:$E,4) -> 0 | H2: =SUMIFS('2. WBS'!$F:$F,'2. WBS'!$G:$G,$A2,'2. WBS'!$E:$E,5) -> 0 | I2: =SUMIFS('2. WBS'!$F:$F,'2. WBS'!$G:$G,$A2,'2. WBS'!$E:$E,6) -> 0 | J2: =SUMIFS('2. WBS'!$F:$F,'2. WBS'!$G:$G,$A2,'2. WBS'!$E:$E,7) -> 0 | K2: =SUMIFS('2. WBS'!$F:$F,'2. WBS'!$G:$G,$A2,'2. WBS'!$E:$E,8) -> 0
A3: Minh | C3: =SUM(D3:K3) -> 0 | D3: =SUMIFS('2. WBS'!$F:$F,'2. WBS'!$G:$G,$A3,'2. WBS'!$E:$E,1) -> 0 | E3: =SUMIFS('2. WBS'!$F:$F,'2. WBS'!$G:$G,$A3,'2. WBS'!$E:$E,2) -> 0 | F3: =SUMIFS('2. WBS'!$F:$F,'2. WBS'!$G:$G,$A3,'2. WBS'!$E:$E,3) -> 0 | G3: =SUMIFS('2. WBS'!$F:$F,'2. WBS'!$G:$G,$A3,'2. WBS'!$E:$E,4) -> 0 | H3: =SUMIFS('2. WBS'!$F:$F,'2. WBS'!$G:$G,$A3,'2. WBS'!$E:$E,5) -> 0 | I3: =SUMIFS('2. WBS'!$F:$F,'2. WBS'!$G:$G,$A3,'2. WBS'!$E:$E,6) -> 0 | J3: =SUMIFS('2. WBS'!$F:$F,'2. WBS'!$G:$G,$A3,'2. WBS'!$E:$E,7) -> 0 | K3: =SUMIFS('2. WBS'!$F:$F,'2. WBS'!$G:$G,$A3,'2. WBS'!$E:$E,8) -> 0
A4: Nhật | C4: =SUM(D4:K4) -> 0 | D4: =SUMIFS('2. WBS'!$F:$F,'2. WBS'!$G:$G,$A4,'2. WBS'!$E:$E,1) -> 0 | E4: =SUMIFS('2. WBS'!$F:$F,'2. WBS'!$G:$G,$A4,'2. WBS'!$E:$E,2) -> 0 | F4: =SUMIFS('2. WBS'!$F:$F,'2. WBS'!$G:$G,$A4,'2. WBS'!$E:$E,3) -> 0 | G4: =SUMIFS('2. WBS'!$F:$F,'2. WBS'!$G:$G,$A4,'2. WBS'!$E:$E,4) -> 0 | H4: =SUMIFS('2. WBS'!$F:$F,'2. WBS'!$G:$G,$A4,'2. WBS'!$E:$E,5) -> 0 | I4: =SUMIFS('2. WBS'!$F:$F,'2. WBS'!$G:$G,$A4,'2. WBS'!$E:$E,6) -> 0 | J4: =SUMIFS('2. WBS'!$F:$F,'2. WBS'!$G:$G,$A4,'2. WBS'!$E:$E,7) -> 0 | K4: =SUMIFS('2. WBS'!$F:$F,'2. WBS'!$G:$G,$A4,'2. WBS'!$E:$E,8) -> 0
A5: Tuấn | C5: =SUM(D5:K5) -> 0 | D5: =SUMIFS('2. WBS'!$F:$F,'2. WBS'!$G:$G,$A5,'2. WBS'!$E:$E,1) -> 0 | E5: =SUMIFS('2. WBS'!$F:$F,'2. WBS'!$G:$G,$A5,'2. WBS'!$E:$E,2) -> 0 | F5: =SUMIFS('2. WBS'!$F:$F,'2. WBS'!$G:$G,$A5,'2. WBS'!$E:$E,3) -> 0 | G5: =SUMIFS('2. WBS'!$F:$F,'2. WBS'!$G:$G,$A5,'2. WBS'!$E:$E,4) -> 0 | H5: =SUMIFS('2. WBS'!$F:$F,'2. WBS'!$G:$G,$A5,'2. WBS'!$E:$E,5) -> 0 | I5: =SUMIFS('2. WBS'!$F:$F,'2. WBS'!$G:$G,$A5,'2. WBS'!$E:$E,6) -> 0 | J5: =SUMIFS('2. WBS'!$F:$F,'2. WBS'!$G:$G,$A5,'2. WBS'!$E:$E,7) -> 0 | K5: =SUMIFS('2. WBS'!$F:$F,'2. WBS'!$G:$G,$A5,'2. WBS'!$E:$E,8) -> 0
A7: Cộng mọi người | C7: =SUM(C2:C5) -> 0
A8: TRẦN TẢI | B8: 4 người × 8 tuần × ~4,3 ngày ≈ 138 ngày — tổng WBS ≈ 146. Vượt ở nhóm "Nên làm/Có thì tốt": ai trên 18 ngày nhượng lại dòng đó, đừng cắt chất lượng.

Sheet 4. Tiến trình & Cổng
A1: Giai đoạn | B1: Tuần | C1: Việc chính (ID WBS) | D1: Cổng kiểm tra — không qua không đi tiếp
A2: 0. Nền | B2: 1 | C2: 1–6, 12, 13, 14 | D2: 4 máy nền chung; upload ra thông số hình học THẬT
A3: 1. Luồng chính (core flow) | B3: 1–2 | C3: 5–11, 15–25, 27–29 | D3: G-A: 1 đơn chạy hết chuỗi bằng cầu đánh dấu đã trả, không dòng nào từ dữ liệu mẫu; khách theo dõi realtime được
A4: 2. Xử lý bất thường | B4: 3 | C4: 18, 31, 33–40, 49 | D4: in hỏng 80% thời lượng ⇒ máy khác trong ≤30s mà khách không trễ
A5: 3. Quản trị | B5: 4 | C5: 7–9, 30, 32, 39, 42–47 | D5: admin đổi luật có hiệu lực ≤1 phút không khởi động lại; lab chỉ thấy việc của mình
A6: 4. Nghiên cứu | B6: 5–6 | C6: 45, 48, 50, 51 | D6: 1 lệnh ra bảng 4 chiến lược; cùng hạt giống cho cùng kết quả
A7: 5. Chốt | B7: 7–8 | C7: 24, 26, 52, 53, 54 | D7: G-B: cổng 16 chỉ số đạt + đơn SEPay sandbox + 3 màn diễn tập 2 lần
A9: TRẢ LỜI CÂU HỎI "core flow tuần nào?" | B9: Tuần 1 bắt đầu, cổng G-A cuối tuần 2. Không có giai đoạn làm đẹp trước khi luồng chính chạy thật.

Sheet 5. Ai làm màn nào
A1: Màn hình / thư mục FE | B1: Chủ (nhóm) | C1: Việc WBS động vào | D1: Luật để không giẫm nhau
A2: features/quotes (trang đặt hàng) | B2: Nhóm Đơn hàng—Thanh toán | C2: 10, 22, 23 | D2: Nhóm Engine chỉ sửa component QuoteResult của mình, không sửa trang
A3: features/quotes/QuoteResult (mới) | B3: Nhóm Engine | C3: 15, 17 | D3: Đọc DTO /quotes/{id}; FE khác không tự tính giá
A4: features/tracking, notifications | B4: Nhóm Cam kết | C4: 19, 20, 27, 49 | D4: Nhóm khác chỉ PHÁT event tên đã khóa, không sửa màn của nhau
A5: features/lab | B5: Nhóm Xưởng in | C5: 21, 32–35, 46
A6: features/hub | B6: Nhóm Hub | C6: 28, 29, 40 | D6: Nút "in lại" chỉ gọi API; logic gán lại của Engine
A7: features/admin | B7: Nhóm Nền tảng | C7: 11, 30, 42, 44 | D7: thêm cột form = sửa hợp đồng trước
A8: features/auth, account | B8: Nhóm Nền tảng | C8: 3, 5, 8, 9 | D8: 3D đăng nhập giữ nguyên; số liệu phải từ API, không hardcode
A9: features/ops (DecisionLog/Refunds/Reports) | B9: tách 3 thư mục: Engine / Đơn hàng / Hub-Báo cáo | C9: 31, 47, 26, 48 | D9: không dùng file chung trong ops
A10: shared/, routes, theme, apiClient, HomeHeader | B10: CHỦ VỎ (Nhóm Nền tảng) | C10: mọi màn cần route | D10: ai cần route/menu: PR 1 dòng, chủ vỏ hợp nhất; cấm refactor chung khi chưa xin
A12: 4 QUY TẮC CHỌN VIỆC
A13: ① Chọn việc = chiếm thư mục đó TRONG TUẦN ĐÓ. 1 thư mục — 1 tuần — 1 người. Hai người cùng muốn ⇒ đổi tuần.
A14: ② Bắt tay bằng hợp đồng + event + props, không bằng sửa file người khác. Cần gì ⇒ ghi chú vào việc của họ.
A15: ③ shared/vỏ: chỉ chủ vỏ hợp nhất.
A16: ④ Nhánh theo việc, hợp nhất hằng đêm; nhánh chạm file chung không sống quá 3 ngày.
