Workbook

Sheet Function map
A1: F | B1: Function | C1: Scope (module BE + folder FE) | D1: Ghề đề xuất (hồ sơ kỹ năng — TỰ PICK, không gán tên) | E1: Task | F1: Σ ngày
A2: F1 | B2: Danh tính, phân quyền & audit | C2: Customer/auth + shared middleware · features/auth,account,admin/Users | D2: Ghế Nhà máy (sysadmin tính) | E2: 7 | F2: 16
A3: F2 | B3: Danh mục & cấu hình chính sách | C3: modules/Admin (hiện rỗng) · features/admin | D3: Ghế Nhà máy | E3: 3 | F3: 10
A4: F3 | B4: Engine lõi: estimate–price–filter–score–assign–repair–log | C4: modules/Scheduling · features/quotes,ops | D4: Ghế Engine — KÈM F9, không chia đôi | E4: 11 | F4: 33
A5: F4 | B5: Sản xuất & kho Lab | C5: modules/Lab (rỗng→migrate code từ Scheduling sang dần) · features/lab | D5: Ghế Xưởng (cầu nối lab đối tác) | E5: 6 | F5: 15
A6: F5 | B6: Chất lượng & hoàn tất (hub) | C6: modules/Hub (rỗng) · features/hub | D6: Ghế Nhà máy → nhường Ghế Xưởng nếu nghẽn sau G-A | E6: 4 | F6: 13
A7: F6 | B7: Đơn hàng & dòng tiền (SEPay) | C7: modules/Customer payments · features/checkout,ops/Refunds | D7: Ghế Tiền & Khách (integration webhook) | E7: 3 | F7: 10
A8: F7 | B8: Cam kết & thông báo | C8: shared NotificationService + SignalR publisher · features/tracking,notifications,reprint | D8: Ghế Tiền & Khách | E8: 4 | F8: 8
A9: F8 | B9: Nền tảng (contract, seed, tests, staging) | C9: Api + Infrastructure.Shared + tests/ · — | D9: Ghế Nhà máy | E9: 4 | F9: 6
A10: F9 | B10: NGHIÊN CỨU: simulator + evaluation + calibration | C10: tools/Simulator + tests · — | D10: Ghế Engine (sau gate G-A) | E10: 5 | F10: 20
A11: F10 | B11: Hồ sơ: state tables, ERD, phiếu, SRS/SDD, slides | C11: documentation/ · — | D11: Mỗi ghế tự phần của mình + Nhóm trưởng | E11: 5 | F11: 10
A13: HIỆN TRẠNG (audit 25/09) | B13: 0/43 FR ĐỦ · 18 MỘT PHẦN · 25 CHƯA CÓ — nguồn chân lý: plan file spicy-nibbling-quiche.md | E13: 63 | F13: 141

Sheet Task List
A1: STT | B1: F | C1: Task | D1: CỤ THỂ (endpoint / bảng / file / job) | E1: Trace (FR/BR/NFR) | F1: Loại | G1: Phase | H1: Tuần | I1: ƯL | J1: Ưu tiên | K1: Chủ trì (▼) | L1: Tình trạng (▼) | M1: Definition of Done | N1: Ghi chú
A2: 1 | B2: F8 | C2: Họp D0: khóa API contract + quy ước repo | D2: • contracts/openapi.yaml: DTO Order/Quote/Job/Slot + event tên • FE: thống nhất features/<F#>/ • CI: build+test mỗi PR | E2: nền mọi FR | F2: 🆕 | G2: 0 | H2: 1 | I2: 1 | J2: Must | L2: Chưa làm | M2: 4 máy pull chạy; sửa schema phải sửa openapi trước
A3: 2 | B3: F8 | C3: Seed dựng lại theo schema mới | D3: • users/roles DB, stock, 1 lab "doi-tac" + machines spec THẬT của lab đối tác • script demo-reset | E3: — | F3: 🔌 | G3: 0 | H3: 1 | I3: 1 | J3: Must | L3: Chưa làm | M3: 1 lệnh reset; data demo không còn là chỗ dựa cho flow thật
A4: 3 | B4: F10 | C4: Bảng chuyển trạng thái Job/Order/Quote (B9) | D4: • state table + diagram vào 16/design; encode enum + guard trong Order.cs/Job.cs | E4: B9 nợ · BR-SCHED-007 | F4: 🆕 | G4: 0 | H4: 1 | I4: 2 | J4: Must | L4: Chưa làm | M4: mọi transition sau này code theo bảng này, không enum trôi nổi | N4: làm TRƯỚC khi code F5 progression
A5: 4 | B5: F8 | C5: Integration test host | D5: • Testcontainers Postgres + WebApplicationFactory — file test ĐẦU TIÊN (repo đang 0) • ca: golden path + race placement | E5: NFR-REL-004 · top-10 #10 | F5: 🆕 | G5: 1 | H5: 2 | I5: 3 | J5: Must | L5: Chưa làm | M5: `dotnet test` xanh là bằng chứng, không phải mắt thấy
A6: 5 | B6: F1 | C6: Users/Roles DB thay DemoRoles | D6: • bảng user_roles; claim JWT từ DB; seed 6 role; bỏ hardcode email lab@/qc@/ops@ • migration + backfill | E6: CUST-001 · ADMIN-001 · BR-ACCESS-005 | F6: 🔌 | G6: 0 | H6: 1 | I6: 3 | J6: Must | L6: Chưa làm | M6: tạo user role Lab qua DB → login có claim thật
A7: 6 | B7: F1 | C7: Email verification | D7: • flag Verified + token qua NotificationService (phối hợp F7) • chặn PlaceOrder khi chưa verify | E7: CUST-001 | F7: 🆕 | G7: 0 | H7: 1 | I7: 2 | J7: Must | L7: Chưa làm | M7: đăng ký không verify → không checkout được
A8: 7 | B8: F1 | C8: Address CRUD | D8: • bảng addresses; default; chặn xóa khi còn đơn chưa giao (409) | E8: CUST-001 · UC-026 | F8: 🆕 | G8: 1 | H8: 2 | I8: 2 | J8: Must | L8: Chưa làm | M8: FE checkout chọn address thay gõ tay
A9: 8 | B9: F1 | C9: Audit log append-only | D9: • middleware: actor/action/entity/before/after jsonb; bảng audit_logs; API GET phân quyền admin; KHÔNG có update/delete | E9: ADMIN-004 · BR-CONFIG-002/004 | F9: 🆕 | G9: 3 | H9: 4 | I9: 3 | J9: Must | L9: Chưa làm | M9: mỗi override/config đổi có dấu vết; grep audit_log không API sửa
A10: 9 | B10: F1 | C10: RBAC mọi controller + scope lab | D10: • policy theo 6 role; GetJobsQuery scope lab-of-user (đang để lộ hết); ma trận test 6×endpoints | E10: ACCESS-002 · top-10 #8 | G10: 3 | H10: 4 | I10: 2 | J10: Must | L10: Chưa làm | M10: Lab A gọi API job Lab B ⇒ 403
A11: 10 | B11: F1 | C11: Profile khách + quota storage | D11: • PATCH profile; quota per account khi upload (BR-ACCESS-006) | E11: CUST-002 · ACCESS-006 | F11: 🔌 | G11: 2 | H11: 3 | I11: 2 | J11: Should | L11: Chưa làm | M11: vượt quota ⇒ 409 kèm hướng dẫn
A12: 11 | B12: F1 | C12: Màn Admin user/role | D12: • features/admin/Users.tsx + API status/role | E12: ADMIN-001 · UC-022 | F12: 🆕 | G12: 3 | H12: 4 | I12: 2 | J12: Should | L12: Chưa làm | M12: mở rộng tự không cần DBA
A13: 12 | B13: F3 | C13: NỐI parser STL/OBJ đã viết vào pipeline | D13: • AnalyzeModelJob: tải bytes từ MinIO theo StorageKey → StlMeshParser.AnalyzeAsync (đã tồn tại, chưa được gọi!) + watertight/manifold • gate oversize trong CreateQuote validator | E13: SCHED-001 · CUST-004 · BR-QUOTE-006 | F13: 🔌 | G13: 0 | H13: 1 | I13: 3 | J13: Must | L13: Chưa làm | M13: upload STL thật ⇒ bbox/volume là số hình học, không phải từ sizeBytes
A14: 13 | B14: F3 | C14: Slicing heuristic từ số phân tích | D14: • PrintSlicingService nhận MeshAnalysis thay metadata mock; async qua Hangfire; raw+calibrated fields | E14: SCHED-002 · NFR-PERF-001 | F14: 🔌 | G14: 1 | H14: 1 | I14: 3 | J14: Must | L14: Chưa làm | M14: est time đổi khi đổi layer/infill trên CÙNG model
A15: 14 | B15: F6 | C15: BRIDGE: mark-paid API (tạm thời thay payment) | D15: • POST /api/orders/{id}/mark-paid (ops/admin, reason bắt buộc, audit) → Order.ConfirmPayment(txnId nội bộ) + event như webhook • ĐÁO BỎ khi SEPay tuần 7 — không cho FE khách tự đánh dấu | E15: thay CUST-008 cho G-A · BR-CONFIG-002 | F15: 🆕 | G15: 1 | H15: 2 | I15: 1 | J15: Must | L15: Chưa làm | M15: chuỗi vàng chạy端到 đầu không cần gateway; mọi mark-paid có dấu vết | N15: quyết định 25/09: payment để sau
A16: 15 | B16: F6 | C16: SEPay: QR checkout + webhook + confirm (DỜI TUẦN 7) | D16: • POST /api/checkout →SEPay create ⇒ QR (hết hạn = quote expiry) • webhook: log + PENDING; GỌI API xác nhận giao dịch (đủ tiền+nd) ⇒ mới Order.ConfirmPayment + event • idempotent txnId; return URL chỉ điều hướng, không phải bằng chứng • DB payments(txn unique, token — KHÔNG lưu thẻ); xóa bridge mark-paid | E16: CUST-008 · BR-PAY-001/005 · NFR-SEC-009 | F16: 🆕 | G16: 5 | H16: 7 | I16: 5 | J16: Must | L16: Chưa làm | M16: sandbox txn chạy đầu-cuối; fake webhook ⇒ không commit | N16: xin app/secret SEPay TRƯỚC tuần 7 — decision 25/09: payment để sau
A17: 16 | B17: F3 | C17: Pricing engine về SCHED + version freeze | D17: • PricingService đọc config_pricing_versions (từ F2); quote.config_version_id; test tái lập quote cũ sau đổi giá | E17: SCHED-010 · BR-QUOTE-001..004 | F17: 🔌 | G17: 1 | H17: 2 | I17: 4 | J17: Must | L17: Chưa làm | M17: QuotePricing.cs (Customer, hằng số) bị thay hẳn
A18: 17 | B18: F3 | C18: Speculative quote-time placement | D18: • CreateQuote chạy MachineTimelineService ở chế độ trial (không persist slot) ⇒ promised date THAY +3 ngày + surcharge urgency | E18: SCHED-005 · BR-QUOTE-002 · NFR-PERF-001 | F18: 🆕 | G18: 1 | H18: 2 | I18: 5 | J18: Must | L18: Chưa làm | M18: quote 2 lần cùng lúc khác tải ⇒ 2 ngày giao khác nhau | N18: linh hồn đề tài
A19: 18 | B19: F3 | C19: Decompose thật từ quote_items + chống chồng slot | D19: • OrderConfirmed→jobs: spec đọc MeshAnalysis+config, bỏ hằng số 120³/qty×30g/60ph • slot unique(machine,from,to) hoặc lock per-machine trong Assign | E19: SCHED-006 · NFR-REL-004 | F19: 🔌 | G19: 1 | H19: 2 | I19: 4 | J19: Must | L19: Chưa làm | M19: race test (F8) pass
A20: 19 | B20: F4 | C20: Accept/DECLINE + countdown | D20: • POST decline(reason enum) + response_deadline_at; UI JobInbox đếm ngược | E20: LAB-004 · BR-ASSIGN-005/006 | G20: 1 | H20: 2 | I20: 2 | J20: Must | L20: Chưa làm | M20: decline ⇒ event; countdown thấy được
A21: 20 | B21: F5 | C21: Batch receipt + reconcile | D21: • Hub: batches/batch_items; POST receipt(code) per-job RECEIVED/MISSING ⇒ incident + notify | E21: HUB-001 · BR-QC-010 | F21: 🆕 | G21: 1 | H21: 2 | I21: 3 | J21: Must | L21: Chưa làm | M21: MISSING ⇒ Lab + Ops nhận thông báo
A22: 21 | B22: F4 | C22: Handover + IN_TRANSIT | D22: • POST handover(jobIds, carrier, waybill) tạo batch code; state mới | E22: UC-015 · BR-SCHED-009 | F22: 🆕 | G22: 1 | H22: 2 | I22: 2 | J22: Should | L22: Chưa làm | M22: nối F5 receipt
A23: 22 | B23: F5 | C23: Consolidation + gate pack + TransitionTo | D23: • pack chặn nếu còn item chưa PASSED_QC (409 + outstanding list); ship(waybill); delivered ⇒ DeliveredAt + mở window; API nội bộ gọi Order.TransitionTo từ chuỗi job/pack/deliver (hiện không ai gọi) | E23: HUB-004/005 · QC-008/009 | F23: 🆕 | G23: 1 | H23: 2 | I23: 4 | J23: Must | L23: Chưa làm | M23: đơn đi hết InProduction→QC→Shipping→Delivered mà KHÔNG cần seeder | N23: chốt G-A
A24: 23 | B24: F7 | C24: SignalR publisher + tracking FE | D24: • IHubContext publish trong event handlers; FE import hubClient + polling fallback 15s; trang tracking detail | E24: CUST-009 · UC-003 | F24: 🔌 | G24: 1 | H24: 2 | I24: 2 | J24: Must | L24: Chưa làm | M24: lab bấm state ⇒ tab khách đổi <15s
A25: 24 | B25: F7 | C25: NotificationService (email) | D25: • interface + impl SMTP/SendGrid; templates: welcome/verify/paid/assigned/qc-fail/shipped/delay; mọi message ẩn tên lab; outbox table để test | E25: BR-NOTIFY-001 · F7 | F25: 🆕 | G25: 1 | H25: 2 | I25: 3 | J25: Must | L25: Chưa làm | M25: mỗi event đúng 1 email tới đúng role
A26: 25 | B26: F3 | C26: Rescheduler handler | D26: • IPipelineCommand/Handler cho ReschedulingTriggeredEvent (đang emit 0 handler): only NOT_STARTED, budget 30s, fallback giữ nguyên, job IN_PROGRESS khóa | E26: SCHED-007 · BR-RESCHED-001/002 · SCHED-007 | F26: 🆕 | G26: 2 | H26: 3 | I26: 4 | J26: Must | L26: Chưa làm | M26: test: fail ở 80% ⇒ slot mới <30s, khách không trễ nếu còn slack
A27: 26 | B27: F3 | C27: Reprint URGENT + trần 2 | D27: • ReprintService: copy config, deadline=original, priority; count>2 ⇒ escalate event | E27: RESCHED-003/004 · UC-013 | F27: 🆕 | G27: 2 | H27: 3 | I27: 2 | J27: Must | L27: Chưa làm | M27: QC fail ⇒ URGENT đúng lịch
A28: 27 | B28: F3 | C28: Decision log persist + API | D28: • decision_log(job, candidates jsonb, scores, config_version, actor) ghi CÙNG txn assign (fail ⇒ rollback); GET /ops/decisions/{jobId} | E28: SCHED-009 · BR-ASSIGN-004 | F28: 🆕 | G28: 2 | H28: 3 | I28: 2 | J28: Must | L28: Chưa làm | M28: trace 5 job random đủ liệu
A29: 28 | B29: F3 | C29: Auto-decline 2h + At-risk scanner | D29: • RecurringJob /5ph: deadline quá ⇒ decline(timeout); /15ph: slack<4h(cfg) ⇒ at_risk view + event | E29: ASSIGN-005 · BR-OPS-007 | F29: 🆕 | G29: 2 | H29: 3 | I29: 3 | J29: Must | L29: Chưa làm | M29: im lặng = tự từ chối; cận hẹn = đỏ
A30: 29 | B30: F3 | C30: Filter += inventory + standing + adversarial suite | D30: • CapabilityFilter đọc stock F4; view standing; tests/ InfeasibleSuite 30 ca độc lập scoring | E30: SCHED-003 · NFR-REL-005 | F30: 🔌 | G30: 2 | H30: 3 | I30: 2 | J30: Must | L30: Chưa làm | M30: 0 vi phạm trong suite
A31: 30 | B31: F4 | C31: Inventory đúng nghĩa | D31: • material_stock(material,color,grams,reserved); reserve-accept / settle-DONE / release-cancel; low-stock alert; form nhập | E31: LAB-003 · BR-ASSIGN-001(in) | F31: 🆕 | G31: 2 | H31: 3 | I31: 4 | J31: Must | L31: Chưa làm | M31: stock 0 ⇒ F3 loại đúng tổ hợp
A32: 31 | B32: F4 | C32: Incident + ảnh → sự kiện | D32: • POST incidents(type, stagePct, photos[] MinIO) ⇒ event rescheduler; nút Report trên Queue | E32: LAB-005 · UC-005 A1/A2 | F32: 🔌 | G32: 2 | H32: 3 | I32: 2 | J32: Must | L32: Chưa làm | M32: MACHINE_DOWN ⇒ máy rời filter
A33: 32 | B33: F5 | C33: Inspection nâng cấp | D33: • verdict + checklist_version + ảnh bắt buộc + defect + attribution + qc_costs(lab|platform); fail⇒event F3 | E33: HUB-002/003 · BR-QC-002..007 | F33: 🔌 | G33: 2 | H33: 3 | I33: 4 | J33: Must | L33: Chưa làm | M33: fail đủ hồ sơ mới cho reprint
A34: 33 | B34: F6 | C34: Refund + đối soát (dời sau SEPay) | D34: • ops approve full/partial-item; idempotency key txn+attempt; SLA 5 ngày warn; T-1 reconcile payments×orders, lệch ⇒ freeze txn | E34: ANAL-005 · BR-PAY-004/006 · NFR-SEC-009 | F34: 🆕 | G34: 5 | H34: 7 | I34: 5 | J34: Must | L34: Chưa làm | M34: gọi refund 2 lần ⇒ 1 kết quả; report đối soát | N34: phụ thuộc SEPay — làm liền sau task đó
A35: 34 | B35: F7 | C35: Flow đổi ngày giao (B16) | D35: • ops tạo request (reason ∈ 3 điều kiện) → token link khách approve/decline; declined ⇒ đường refund | E35: NFR-REL-006 · BR-NOTIFY-002 | F35: 🆕 | G35: 2 | H35: 3 | I35: 1 | J35: Should | L35: Chưa làm | M35: không có approve ⇒ date không đổi
A36: 35 | B36: F2 | C36: Config parameter sets có version | D36: • bảng config(group,key,value,version,active); API PUT/GET; cache đọc ≤1 phút; endpoint + FE admin/Configs preview diff | E36: ADMIN-002 · CONFIG-001..003 · NFR-MAINT-005 | F36: 🆕 | G36: 3 | H36: 4 | I36: 4 | J36: Must | L36: Chưa làm | M36: đổi expiry/weights không restart; F3/F6 đọc từ đây
A37: 36 | B37: F2 | C37: Catalogue DB thay const | D37: • materials/colors/technologies/grades (+rate refs); FE admin/Catalog; deprecate-only in-use; bỏ MATERIALS const FE | E37: ADMIN-003 · CONFIG-003 | F37: 🆕 | G37: 3 | H37: 4 | I37: 4 | J37: Must | L37: Chưa làm | M37: thêm PETG-Grey ⇒ hiện ở config checkout
A38: 37 | B38: F2 | C38: Checklist + taxonomy manager | D38: • checklists(grade,version,items jsonb), defect_taxonomy; inspection đọc version active | E38: ADMIN-005 · BR-QC-002 | F38: 🆕 | G38: 3 | H38: 4 | I38: 2 | J38: Should | L38: Chưa làm | M38: ca chạy giữ version cũ
A39: 38 | B39: F3 | C39: Weights/scoring đọc config động | D39: • AssignmentScorer nhận weights từ F2 (thay const 0.35...) | E39: SCHED-004 · ASSIGN-002 | F39: 🔌 | G39: 3 | H39: 4 | I39: 1 | J39: Should | L39: Chưa làm | M39: đổi weight ⇒ assignment kế tiếp đổi theo
A40: 39 | B40: F4 | C40: Lab self-registration + approval | D40: • form lab (calendar, transfer); status PENDING; admin approve; bỏ gate RequireOps | E40: LAB-001 · BR-OPS-005/006 · UC-014 | F40: 🆕 | G40: 3 | H40: 4 | I40: 3 | J40: Must | L40: Chưa làm | M40: lab đối tác tự onboard bằng form
...

Sheet TV
A1: Tên | B1: Ghế đăng ký | C1: TẢI TỔNG (tự tính) | D1: T1 | E1: T2 | F1: T3 | G1: T4 | H1: T5 | I1: T6 | J1: T7 | K1: T8
A2: Tân | C2: =SUM(D2:K2) | D2: =SUMIFS('Task List'!$I:$I,'Task List'!$K:$K,$A2,'Task List'!$H:$H,1) | E2: =SUMIFS('Task List'!$I:$I,'Task List'!$K:$K,$A2,'Task List'!$H:$H,2) | F2: =SUMIFS('Task List'!$I:$I,'Task List'!$K:$K,$A2,'Task List'!$H:$H,3) | G2: =SUMIFS('Task List'!$I:$I,'Task List'!$K:$K,$A2,'Task List'!$H:$H,4) | H2: =SUMIFS('Task List'!$I:$I,'Task List'!$K:$K,$A2,'Task List'!$H:$H,5) | I2: =SUMIFS('Task List'!$I:$I,'Task List'!$K:$K,$A2,'Task List'!$H:$H,6) | J2: =SUMIFS('Task List'!$I:$I,'Task List'!$K:$K,$A2,'Task List'!$H:$H,7) | K2: =SUMIFS('Task List'!$I:$I,'Task List'!$K:$K,$A2,'Task List'!$H:$H,8)
A3: Minh | C3: =SUM(D3:K3) | D3: =SUMIFS('Task List'!$I:$I,'Task List'!$K:$K,$A3,'Task List'!$H:$H,1) | E3: =SUMIFS('Task List'!$I:$I,'Task List'!$K:$K,$A3,'Task List'!$H:$H,2) | F3: =SUMIFS('Task List'!$I:$I,'Task List'!$K:$K,$A3,'Task List'!$H:$H,3) | G3: =SUMIFS('Task List'!$I:$I,'Task List'!$K:$K,$A3,'Task List'!$H:$H,4) | H3: =SUMIFS('Task List'!$I:$I,'Task List'!$K:$K,$A3,'Task List'!$H:$H,5) | I3: =SUMIFS('Task List'!$I:$I,'Task List'!$K:$K,$A3,'Task List'!$H:$H,6) | J3: =SUMIFS('Task List'!$I:$I,'Task List'!$K:$K,$A3,'Task List'!$H:$H,7) | K3: =SUMIFS('Task List'!$I:$I,'Task List'!$K:$K,$A3,'Task List'!$H:$H,8)
A4: Nhật | C4: =SUM(D4:K4) | D4: =SUMIFS('Task List'!$I:$I,'Task List'!$K:$K,$A4,'Task List'!$H:$H,1) | E4: =SUMIFS('Task List'!$I:$I,'Task List'!$K:$K,$A4,'Task List'!$H:$H,2) | F4: =SUMIFS('Task List'!$I:$I,'Task List'!$K:$K,$A4,'Task List'!$H:$H,3) | G4: =SUMIFS('Task List'!$I:$I,'Task List'!$K:$K,$A4,'Task List'!$H:$H,4) | H4: =SUMIFS('Task List'!$I:$I,'Task List'!$K:$K,$A4,'Task List'!$H:$H,5) | I4: =SUMIFS('Task List'!$I:$I,'Task List'!$K:$K,$A4,'Task List'!$H:$H,6) | J4: =SUMIFS('Task List'!$I:$I,'Task List'!$K:$K,$A4,'Task List'!$H:$H,7) | K4: =SUMIFS('Task List'!$I:$I,'Task List'!$K:$K,$A4,'Task List'!$H:$H,8)
A5: Tuấn | C5: =SUM(D5:K5) | D5: =SUMIFS('Task List'!$I:$I,'Task List'!$K:$K,$A5,'Task List'!$H:$H,1) | E5: =SUMIFS('Task List'!$I:$I,'Task List'!$K:$K,$A5,'Task List'!$H:$H,2) | F5: =SUMIFS('Task List'!$I:$I,'Task List'!$K:$K,$A5,'Task List'!$H:$H,3) | G5: =SUMIFS('Task List'!$I:$I,'Task List'!$K:$K,$A5,'Task List'!$H:$H,4) | H5: =SUMIFS('Task List'!$I:$I,'Task List'!$K:$K,$A5,'Task List'!$H:$H,5) | I5: =SUMIFS('Task List'!$I:$I,'Task List'!$K:$K,$A5,'Task List'!$H:$H,6) | J5: =SUMIFS('Task List'!$I:$I,'Task List'!$K:$K,$A5,'Task List'!$H:$H,7) | K5: =SUMIFS('Task List'!$I:$I,'Task List'!$K:$K,$A5,'Task List'!$H:$H,8)
A7: TỔNG MỌI NGƯỜI | C7: =SUM(C2:C5) | D7: =SUM(D2:D5) | E7: =SUM(E2:E5) | F7: =SUM(F2:F5) | G7: =SUM(G2:G5) | H7: =SUM(H2:H5) | I7: =SUM(I2:I5) | J7: =SUM(J2:J5) | K7: =SUM(K2:K5)
A9: CÁCH PICK | B9: Đọc Function map — cột Ghế đề xuất. Ghế Engine = F3+F9 (1 người, không chia đôi). Ghế Nhà máy quá tải → nhường F5 sau G-A cho Ghế Xưởng.
A10: RULE | B10: 4 người × 8 tuần × 4,3 ngày ≈ 138d có sẵn — danh mục = 141d: CẮT dòng Could trước, rồi mới tính hoãn F9. Muốn xong 6 tuần ("sớm"): chỉ khả thi nếu ghế Engine rảnh 100% và F9 nén còn 12d.
A11: RULE | B11: 2 dòng Must cùng "Tuần" không rơi 1 người. Cột Tình trạng update mỗi tối — 2 Block liên tiếp 2 ngày = họp 15′ cắt Should/Could ngay.

Sheet Phases & Gates
A1: Phase | B1: Tuần | C1: Việc | D1: GATE — không đậu thì KHÔNG đi tiếp
A2: 0 Nền móng | B2: 1 | C2: F8 D0+seed · F1 users/roles/verify · F3 nối parser + slicing · F10 state tables | D2: 4 máy chung nền; upload→analyze ra số THẬT
A3: 1 LUỒNG VÀNG | B3: 1–2 | C3: F6 BRIDGE mark-paid (SEPay dời T7) · F3 freeze pricing + speculative + decompose + chống chồng · F4 accept · F5 hub chain + TransitionTo · F7 realtime + email | D3: G-A: 1 đơn chạy hết chuỗi bằng mark-paid (audit được), không dòng nào từ DemoDataSeeder
A4: 2 Ngoại lệ | B4: 3 | C4: F3 repair/reprint/auto-decline/at-risk/decision-log · F4 inventory/incident · F5 inspection đầy đủ · F7 đổi ngày | D4: in hỏng 80% ⇒ slot mới <30s, khách không mất hẹn
A5: 3 Quản trị | B5: 4 | C5: F2 cả ba · F1 audit/RBAC matrix/user mgmt · F4 registration+self+Gantt · F3 ops viewer | D5: đổi luật ≤1 phút không restart; lab chỉ thấy việc mình
A6: 4 Nghiên cứu | B6: 5–6 | C6: F9 simulator→generator/fault→baselines→calibration auto | D6: 1 lệnh ra bảng 4 chiến lược; seed = kết quả
A7: 5 Đóng ví | B7: 7–8 | C7: F6 SEPay + refund/đối soát (payment để sau — giờ mới làm) · F9 pilot+stress+report · F8 staging · F10 phiếu v1.2/SRS/slide/demo · bug bash rải đều | D7: G-B: NFR-16 pass bảng + 3 kịch bản dượt 2 lần + đơn SEPay sandbox thật
A9: TUẦN 1 LÀ CORE FLOW | B9: Core flow = Phase 0+1 (tuần 1→giữa tuần 2). Không có tuần nào "làm đẹp" trước khi G-A đậu.

Sheet FE Ownership
A1: Surface (file/folder FE) | B1: Chủ mặc định (ghế) | C1: Task động vào | D1: Luật phối hợp
A2: features/quotes/OrderConfigPage + quoteTypes | B2: Ghế Tiền & Khách (F6) | C2: checkout, pricing display, T&C | D2: F3 CHỈ được sửa: chip kết quả báo giá trong con component QuoteResult của F3 mà F6 render — không sửa trang của nhau, nói chuyện qua props/DTO
A3: features/quotes/QuoteResult (mới) | B3: Ghế Engine (F3) | C3: freeze pricing, speculative date/surcharge | D3: F6 đọc DTO /quotes/{id}, không tái tính giá phía FE
A4: features/tracking + notifications | B4: Ghế Tiền & Khách (F7) | C4: timeline, bell, hub client | D4: event names khóa trong contracts/openapi — F4/F5 chỉ PHÁT event, không sửa UI khách
A5: features/lab/** | B5: Ghế Xưởng (F4) | C5: machines, inventory, job inbox, queue, handover, timeline | D5: job state đổi ⇒ server event, F4 không import code F3
A6: features/hub/** | B6: Ghế Nhà máy (F5) | C6: receipt, inspection, fulfillment | D6: nút "reprint" chỉ gọi API ANAL — logic gán lại thuộc F3
A7: features/admin/** (Users, Catalogs, Configs, Checklists) | B7: Ghế Nhà máy (F1+F2) | C7: RBAC, catalogue, params, checklist | D7: form schema lấy từ openapi; thêm field = sửa contract trước
A8: features/auth, account | B8: Ghế Nhà máy (F1) | C8: login/register/verify/addresses | D8: LoginShowcase 3D: CHỈ chủ ghế F1 sửa layout; số liệu động phải qua /network/stats, không hardcode
A9: features/ops/** (Monitor, DecisionLog, Refunds, Reports) | B9: Ghế Engine cho DecisionLog+Override (F3) · Ghế T&K cho Refunds (F6) · Ghế Nhà máy cho Reports (F2/ANAL) | C9: tuần 3–7 | D9: 3 thư mục TÁCH RỜI trong features/ops/ — không file chung
A10: shared/**, routes/AppRoutes, theme, apiClient, HomeHeader | B10: SHELL OWNER: Ghế Nhà máy (F8) | C10: mọi seat xin slot route | D10: đóng băng: sửa qua PR vào chủ shell; route mới = thêm dòng theo template, không refactor chung
A11: tests/ (Unit/Integration) | B11: Ghế Engine (F3 suite NFR) · Ghế Nhà máy (CI + integration host) | C11: W2–W8 | D11: thư mục test mirror theo module — không ai viết test hộ module người khác
A13: 4 QUY TẮC PICK TASK
A14: 1 | B14: Pick task = claim folder tương ứng trong TUẦN đó. 1 folder — 1 tuần — 1 người. Muốn 2 người cùng 1 folder: đổi tuần, không đổi folder.
A15: 2 | B15: Bắt tay qua CONTRACT (openapi + event names + props), không qua sửa file của nhau. Cần gì từ seat khác → ghi vào cột Ghi chú task của họ hoặc issue, seat đó làm.
A16: 3 | B16: shared/ + routes: chỉ SHELL OWNER merge. Ai cần route/menu mới → PR 1 dòng, review 5 phút.
A17: 4 | B17: Branch theo task (f/F3-w2-speculative), merge nightly — cấm branch sống quá 3 ngày chạm shared surface.
